Workbook

Sheet Instructions
A1: PROJECT TASK TRACKER - DAILY, DATE-WISE
A3: HOW THIS WORKBOOK WORKS
A4: 1. Enter every task ONCE on the 'Task Log' sheet. Never retype a task on a new day.
A5: 2. Fill only the coloured columns. White columns are formulas - do not type in them.
A6: 3. If a task is not marked Completed by its Due Date, it is carried forward automatically:
A7: its 'Active Date' rolls to today and it keeps appearing on 'Today's Plan'.
A8: 4. Set Status = Completed and enter the Completed Date - the task closes on that date
A9: and stops rolling forward.
A10: 5. 'Dashboard' is live. Every count and chart recalculates on its own.
A12: TWO DIFFERENT DATES - USE BOTH
A13: Due Date - when YOUR step has to be finished (send quote, prepare kit, follow up DGCA).
A14: Execution / Event Date - the committed date the project itself must happen: the demo date,
... A61: - The web app uses these exact columns, so Excel and the app import/export cleanly.

Sheet Task Log
A1: Task ID | B1: Date Logged | C1: Vertical | D1: Task Description | E1: Client / Customer | F1: Order Type | G1: Priority | H1: Due Date | I1: Execution / Event Date | J1: Event Type | K1: Status | L1: Completed Date | M1: Active Date | N1: Day Status | O1: Days to Event | P1: Ageing (Days) | Q1: Open Seq | R1: Remarks | S1: Assigned To
A2: =IF($D2="","",ROW()-1) | B2: 46274 | C2: Tenders | D2: Submit technical bid documents for surveillance drone tender | E2: State Police Dept | F2: Tender / Bid | G2: High | H2: 46278 | I2: 46284 | J2: Tender Submission | K2: In Progress | M2: =IF($D2="","",IF($K2="Completed",IF($L2="",$H2,$L2),IF($H2="","",IF($H2<TODAY(),TODAY(),$H2)))) | N2: =IF($D2="","",IF($K2="Completed","Completed",IF($H2="","No Due Date",IF($H2<TODAY(),"Carried Forward",IF($H2=TODAY(),"Due Today","Upcoming"))))) | O2: =IF($D2="","",IF($I2="","",IF($K2="Completed","",$I2-TODAY()))) | P2: =IF($D2="","",IF($B2="","",IF($K2="Completed",IF($L2="","",$L2-$B2),TODAY()-$B2))) | Q2: =IF($D2="","",IF($K2="Completed","",MAX($Q$1:$Q1)+1)) | R2: SAMPLE - overdue step, carried forward automatically
A3: =IF($D3="","",ROW()-1) | B3: 46276 | C3: Defence | D3: Arrange flight demo of VTOL unit for evaluation team | E3: MoD - Army Wing | F3: Drone Sale - Govt Order | G3: High | H3: 46280 | I3: 46286 | J3: Demo | K3: In Progress | M3: =IF($D3="","",IF($K3="Completed",IF($L3="",$H3,$L3),IF($H3="","",IF($H3<TODAY(),TODAY(),$H3)))) | N3: =IF($D3="","",IF($K3="Completed","Completed",IF($H3="","No Due Date",IF($H3<TODAY(),"Carried Forward",IF($H3=TODAY(),"Due Today","Upcoming"))))) | O3: =IF($D3="","",IF($I3="","",IF($K3="Completed","",$I3-TODAY()))) | P3: =IF($D3="","",IF($B3="","",IF($K3="Completed",IF($L3="","",$L3-$B3),TODAY()-$B3))) | Q3: =IF($D3="","",IF($K3="Completed","",MAX($Q$1:$Q2)+1)) | R3: SAMPLE - demo date is the committed date
A4: =IF($D4="","",ROW()-1) | B4: 46276 | C4: RPTO Establishment | D4: Follow up DGCA file for new RPTO site approval | E4: Internal | F4: Internal / Admin | G4: Medium | H4: 46283 | I4: 46301 | J4: Go-Live | K4: Not Started | M4: =IF($D4="","",IF($K4="Completed",IF($L4="",$H4,$L4),IF($H4="","",IF($H4<TODAY(),TODAY(),$H4)))) | N4: =IF($D4="","",IF($K4="Completed","Completed",IF($H4="","No Due Date",IF($H4<TODAY(),"Carried Forward",IF($H4=TODAY(),"Due Today","Upcoming"))))) | O4: =IF($D4="","",IF($I4="","",IF($K4="Completed","",$I4-TODAY()))) | P4: =IF($D4="","",IF($B4="","",IF($K4="Completed",IF($L4="","",$L4-$B4),TODAY()-$B4))) | Q4: =IF($D4="","",IF($K4="Completed","",MAX($Q$1:$Q3)+1)) | R4: SAMPLE
A5: =IF($D5="","",ROW()-1) | B5: 46272 | C5: Agri Services | D5: Schedule spraying crew for 120 acre paddy block | E5: Farmer Producer Org | F5: Service / DaaS | G5: Medium | H5: 46275 | I5: 46275 | J5: Site Survey | K5: Completed | L5: 46275 | M5: =IF($D5="","",IF($K5="Completed",IF($L5="",$H5,$L5),IF($H5="","",IF($H5<TODAY(),TODAY(),$H5)))) | N5: =IF($D5="","",IF($K5="Completed","Completed",IF($H5="","No Due Date",IF($H5<TODAY(),"Carried Forward",IF($H5=TODAY(),"Due Today","Upcoming"))))) | O5: =IF($D5="","",IF($I5="","",IF($K5="Completed","",$I5-TODAY()))) | P5: =IF($D5="","",IF($B5="","",IF($K5="Completed",IF($L5="","",$L5-$B5),TODAY()-$B5))) | Q5: =IF($D5="","",IF($K5="Completed","",MAX($Q$1:$Q4)+1)) | R5: SAMPLE - closed, stops rolling
A6: =IF($D6="","",ROW()-1) | B6: 46278 | C6: Redington | D6: Share updated price list and channel margin sheet | E6: Redington India | F6: Drone Sale - Private | G6: Low | H6: 46285 | K6: Not Started | M6: =IF($D6="","",IF($K6="Completed",IF($L6="",$H6,$L6),IF($H6="","",IF($H6<TODAY(),TODAY(),$H6)))) | N6: =IF($D6="","",IF($K6="Completed","Completed",IF($H6="","No Due Date",IF($H6<TODAY(),"Carried Forward",IF($H6=TODAY(),"Due Today","Upcoming"))))) | O6: =IF($D6="","",IF($I6="","",IF($K6="Completed","",$I6-TODAY()))) | P6: =IF($D6="","",IF($B6="","",IF($K6="Completed",IF($L6="","",$L6-$B6),TODAY()-$B6))) | Q6: =IF($D6="","",IF($K6="Completed","",MAX($Q$1:$Q5)+1)) | R6: SAMPLE - no event date, only a due date
A7: =IF($D7="","",ROW()-1) | B7: 46279 | C7: DaaS | D7: Raise invoice for September survey mandays | E7: Private Infra Co | F7: Service / DaaS | G7: High | H7: 46281 | I7: 46282 | J7: Payment / Invoice | K7: In Progress | M7: =IF($D7="","",IF($K7="Completed",IF($L7="",$H7,$L7),IF($H7="","",IF($H7<TODAY(),TODAY(),$H7)))) | N7: =IF($D7="","",IF($K7="Completed","Completed",IF($H7="","No Due Date",IF($H7<TODAY(),"Carried Forward",IF($H7=TODAY(),"Due Today","Upcoming"))))) | O7: =IF($D7="","",IF($I7="","",IF($K7="Completed","",$I7-TODAY()))) | P7: =IF($D7="","",IF($B7="","",IF($K7="Completed",IF($L7="","",$L7-$B7),TODAY()-$B7))) | Q7: =IF($D7="","",IF($K7="Completed","",MAX($Q$1:$Q6)+1)) | R7: SAMPLE
A8: =IF($D8="","",ROW()-1) | M8: =IF($D8="","",IF($K8="Completed",IF($L8="",$H8,$L8),IF($H8="","",IF($H8<TODAY(),TODAY(),$H8)))) | N8: =IF($D8="","",IF($K8="Completed","Completed",IF($H8="","No Due Date",IF($H8<TODAY(),"Carried Forward",IF($H8=TODAY(),"Due Today","Upcoming"))))) | O8: =IF($D8="","",IF($I8="","",IF($K8="Completed","",$I8-TODAY()))) | P8: =IF($D8="","",IF($B8="","",IF($K8="Completed",IF($L8="","",$L8-$B8),TODAY()-$B8))) | Q8: =IF($D8="","",IF($K8="Completed","",MAX($Q$1:$Q7)+1))
A9: =IF($D9="","",ROW()-1) | M9: =IF($D9="","",IF($K9="Completed",IF($L9="",$H9,$L9),IF($H9="","",IF($H9<TODAY(),TODAY(),$H9)))) | N9: =IF($D9="","",IF($K9="Completed","Completed",IF($H9="","No Due Date",IF($H9<TODAY(),"Carried Forward",IF($H9=TODAY(),"Due Today","Upcoming"))))) | O9: =IF($D9="","",IF($I9="","",IF($K9="Completed","",$I9-TODAY()))) | P9: =IF($D9="","",IF($B9="","",IF($K9="Completed",IF($L9="","",$L9-$B9),TODAY()-$B9))) | Q9: =IF($D9="","",IF($K9="Completed","",MAX($Q$1:$Q8)+1))
A10: =IF($D10="","",ROW()-1) | M10: =IF($D10="","",IF($K10="Completed",IF($L10="",$H10,$L10),IF($H10="","",IF($H10<TODAY(),TODAY(),$H10)))) | N10: =IF($D10="","",IF($K10="Completed","Completed",IF($H10="","No Due Date",IF($H10<TODAY(),"Carried Forward",IF($H10=TODAY(),"Due Today","Upcoming"))))) | O10: =IF($D10="","",IF($I10="","",IF($K10="Completed","",$I10-TODAY()))) | P10: =IF($D10="","",IF($B10="","",IF($K10="Completed",IF($L10="","",$L10-$B10),TODAY()-$B10))) | Q10: =IF($D10="","",IF($K10="Completed","",MAX($Q$1:$Q9)+1))
A11: =IF($D11="","",ROW()-1) | M11: =IF($D11="","",IF($K11="Completed",IF($L11="",$H11,$L11),IF($H11="","",IF($H11<TODAY(),TODAY(),$H11)))) | N11: =IF($D11="","",IF($K11="Completed","Completed",IF($H11="","No Due Date",IF($H11<TODAY(),"Carried Forward",IF($H11=TODAY(),"Due Today","Upcoming"))))) | O11: =IF($D11="","",IF($I11="","",IF($K11="Completed","",$I11-TODAY()))) | P11: =IF($D11="","",IF($B11="","",IF($K11="Completed",IF($L11="","",$L11-$B11),TODAY()-$B11))) | Q11: =IF($D11="","",IF($K11="Completed","",MAX($Q$1:$Q10)+1))
A12: =IF($D12="","",ROW()-1) | M12: =IF($D12="","",IF($K12="Completed",IF($L12="",$H12,$L12),IF($H12="","",IF($H12<TODAY(),TODAY(),$H12)))) | N12: =IF($D12="","",IF($K12="Completed","Completed",IF($H12="","No Due Date",IF($H12<TODAY(),"Carried Forward",IF($H12=TODAY(),"Due Today","Upcoming"))))) | O12: =IF($D12="","",IF($I12="","",IF($K12="Completed","",$I12-TODAY()))) | P12: =IF($D12="","",IF($B12="","",IF($K12="Completed",IF($L12="","",$L12-$B12),TODAY()-$B12))) | Q12: =IF($D12="","",IF($K12="Completed","",MAX($Q$1:$Q11)+1))
A13: =IF($D13="","",ROW()-1) | M13: =IF($D13="","",IF($K13="Completed",IF($L13="",$H13,$L13),IF($H13="","",IF($H13<TODAY(),TODAY(),$H13)))) | N13: =IF($D13="","",IF($K13="Completed","Completed",IF($H13="","No Due Date",IF($H13<TODAY(),"Carried Forward",IF($H13=TODAY(),"Due Today","Upcoming"))))) | O13: =IF($D13="","",IF($I13="","",IF($K13="Completed","",$I13-TODAY()))) | P13: =IF($D13="","",IF($B13="","",IF($K13="Completed",IF($L13="","",$L13-$B13),TODAY()-$B13))) | Q13: =IF($D13="","",IF($K13="Completed","",MAX($Q$1:$Q12)+1))
A14: =IF($D14="","",ROW()-1) | M14: =IF($D14="","",IF($K14="Completed",IF($L14="",$H14,$L14),IF($H14="","",IF($H14<TODAY(),TODAY(),$H14)))) | N14: =IF($D14="","",IF($K14="Completed","Completed",IF($H14="","No Due Date",IF($H14<TODAY(),"Carried Forward",IF($H14=TODAY(),"Due Today","Upcoming"))))) | O14: =IF($D14="","",IF($I14="","",IF($K14="Completed","",$I14-TODAY()))) | P14: =IF($D14="","",IF($B14="","",IF($K14="Completed",IF($L14="","",$L14-$B14),TODAY()-$B14))) | Q14: =IF($D14="","",IF($K14="Completed","",MAX($Q$1:$Q13)+1))
A15: =IF($D15="","",ROW()-1) | M15: =IF($D15="","",IF($K15="Completed",IF($L15="",$H15,$L15),IF($H15="","",IF($H15<TODAY(),TODAY(),$H15)))) | N15: =IF($D15="","",IF($K15="Completed","Completed",IF($H15="","No Due Date",IF($H15<TODAY(),"Carried Forward",IF($H15=TODAY(),"Due Today","Upcoming"))))) | O15: =IF($D15="","",IF($I15="","",IF($K15="Completed","",$I15-TODAY()))) | P15: =IF($D15="","",IF($B15="","",IF($K15="Completed",IF($L15="","",$L15-$B15),TODAY()-$B15))) | Q15: =IF($D15="","",IF($K15="Completed","",MAX($Q$1:$Q14)+1))
A16: =IF($D16="","",ROW()-1) | M16: =IF($D16="","",IF($K16="Completed",IF($L16="",$H16,$L16),IF($H16="","",IF($H16<TODAY(),TODAY(),$H16)))) | N16: =IF($D16="","",IF($K16="Completed","Completed",IF($H16="","No Due Date",IF($H16<TODAY(),"Carried Forward",IF($H16=TODAY(),"Due Today","Upcoming"))))) | O16: =IF($D16="","",IF($I16="","",IF($K16="Completed","",$I16-TODAY()))) | P16: =IF($D16="","",IF($B16="","",IF($K16="Completed",IF($L16="","",$L16-$B16),TODAY()-$B16))) | Q16: =IF($D16="","",IF($K16="Completed","",MAX($Q$1:$Q15)+1))
A17: =IF($D17="","",ROW()-1) | M17: =IF($D17="","",IF($K17="Completed",IF($L17="",$H17,$L17),IF($H17="","",IF($H17<TODAY(),TODAY(),$H17)))) | N17: =IF($D17="","",IF($K17="Completed","Completed",IF($H17="","No Due Date",IF($H17<TODAY(),"Carried Forward",IF($H17=TODAY(),"Due Today","Upcoming"))))) | O17: =IF($D17="","",IF($I17="","",IF($K17="Completed","",$I17-TODAY()))) | P17: =IF($D17="","",IF($B17="","",IF($K17="Completed",IF($L17="","",$L17-$B17),TODAY()-$B17))) | Q17: =IF($D17="","",IF($K17="Completed","",MAX($Q$1:$Q16)+1))
A18: =IF($D18="","",ROW()-1) | M18: =IF($D18="","",IF($K18="Completed",IF($L18="",$H18,$L18),IF($H18="","",IF($H18<TODAY(),TODAY(),$H18)))) | N18: =IF($D18="","",IF($K18="Completed","Completed",IF($H18="","No Due Date",IF($H18<TODAY(),"Carried Forward",IF($H18=TODAY(),"Due Today","Upcoming"))))) | O18: =IF($D18="","",IF($I18="","",IF($K18="Completed","",$I18-TODAY()))) | P18: =IF($D18="","",IF($B18="","",IF($K18="Completed",IF($L18="","",$L18-$B18),TODAY()-$B18))) | Q18: =IF($D18="","",IF($K18="Completed","",MAX($Q$1:$Q17)+1))
A19: =IF($D19="","",ROW()-1) | M19: =IF($D19="","",IF($K19="Completed",IF($L19="",$H19,$L19),IF($H19="","",IF($H19<TODAY(),TODAY(),$H19)))) | N19: =IF($D19="","",IF($K19="Completed","Completed",IF($H19="","No Due Date",IF($H19<TODAY(),"Carried Forward",IF($H19=TODAY(),"Due Today","Upcoming"))))) | O19: =IF($D19="","",IF($I19="","",IF($K19="Completed","",$I19-TODAY()))) | P19: =IF($D19="","",IF($B19="","",IF($K19="Completed",IF($L19="","",$L19-$B19),TODAY()-$B19))) | Q19: =IF($D19="","",IF($K19="Completed","",MAX($Q$1:$Q18)+1))
... A500: =IF($D500="","",ROW()-1) | M500: =IF($D500="","",IF($K500="Completed",IF($L500="",$H500,$L500),IF($H500="","",IF($H500<TODAY(),TODAY(),$H500)))) | N500: =IF($D500="","",IF($K500="Completed","Completed",IF($H500="","No Due Date",IF($H500<TODAY(),"Carried Forward",IF($H500=TODAY(),"Due Today","Upcoming"))))) | O500: =IF($D500="","",IF($I500="","",IF($K500="Completed","",$I500-TODAY()))) | P500: =IF($D500="","",IF($B500="","",IF($K500="Completed",IF($L500="","",$L500-$B500),TODAY()-$B500))) | Q500: =IF($D500="","",IF($K500="Completed","",MAX($Q$1:$Q499)+1))

Sheet Projects
A1: Project ID | B1: Project Name | C1: Vertical | D1: Requirements | E1: Start Date | F1: End Date | G1: L1 | H1: BOQ | I1: TEC | J1: Awarded | K1: Procurement | L1: Inventory | M1: Production | N1: QC | O1: Testing | P1: Dispatch | Q1: Delivered | R1: Payment | S1: Documentation | T1: Failed | U1: % Complete | V1: Overall Status
A2: PRJ-001 | B2: VTOL Unit — MoD Surveillance Order | C2: Defence | D2: 20kg payload VTOL, thermal + EO camera, 2hr endurance | E2: 46266 | F2: 46371 | G2: Done | H2: Done | I2: Done | J2: Done | K2: Pending | U2: =IF($B2="","",IF(COUNTIF(G2:T2,"<>")=0,0,ROUND(COUNTIF(G2:T2,"Done")/COUNTIF(G2:T2,"<>")*100,0))) | V2: =IF($B2="","",IF($T2="Done","Failed",IF(U2=100,"Completed","In Progress")))
A3: PRJ-002 | B3: Agri Drone Batch — Redington Channel | C3: Redington | D3: 6 units, spraying config, dealer training included | E3: 46249 | F3: 46305 | G3: Done | H3: Done | I3: Done | J3: Done | K3: Done | L3: Done | M3: Pending | R3: Pending | S3: Pending | U3: =IF($B3="","",IF(COUNTIF(G3:T3,"<>")=0,0,ROUND(COUNTIF(G3:T3,"Done")/COUNTIF(G3:T3,"<>")*100,0))) | V3: =IF($B3="","",IF($T3="Done","Failed",IF(U3=100,"Completed","In Progress")))
U4: =IF($B4="","",IF(COUNTIF(G4:T4,"<>")=0,0,ROUND(COUNTIF(G4:T4,"Done")/COUNTIF(G4:T4,"<>")*100,0))) | V4: =IF($B4="","",IF($T4="Done","Failed",IF(U4=100,"Completed","In Progress")))
U5: =IF($B5="","",IF(COUNTIF(G5:T5,"<>")=0,0,ROUND(COUNTIF(G5:T5,"Done")/COUNTIF(G5:T5,"<>")*100,0))) | V5: =IF($B5="","",IF($T5="Done","Failed",IF(U5=100,"Completed","In Progress")))
U6: =IF($B6="","",IF(COUNTIF(G6:T6,"<>")=0,0,ROUND(COUNTIF(G6:T6,"Done")/COUNTIF(G6:T6,"<>")*100,0))) | V6: =IF($B6="","",IF($T6="Done","Failed",IF(U6=100,"Completed","In Progress")))
U7: =IF($B7="","",IF(COUNTIF(G7:T7,"<>")=0,0,ROUND(COUNTIF(G7:T7,"Done")/COUNTIF(G7:T7,"<>")*100,0))) | V7: =IF($B7="","",IF($T7="Done","Failed",IF(U7=100,"Completed","In Progress")))
U8: =IF($B8="","",IF(COUNTIF(G8:T8,"<>")=0,0,ROUND(COUNTIF(G8:T8,"Done")/COUNTIF(G8:T8,"<>")*100,0))) | V8: =IF($B8="","",IF($T8="Done","Failed",IF(U8=100,"Completed","In Progress")))
U9: =IF($B9="","",IF(COUNTIF(G9:T9,"<>")=0,0,ROUND(COUNTIF(G9:T9,"Done")/COUNTIF(G9:T9,"<>")*100,0))) | V9: =IF($B9="","",IF($T9="Done","Failed",IF(U9=100,"Completed","In Progress")))
U10: =IF($B10="","",IF(COUNTIF(G10:T10,"<>")=0,0,ROUND(COUNTIF(G10:T10,"Done")/COUNTIF(G10:T10,"<>")*100,0))) | V10: =IF($B10="","",IF($T10="Done","Failed",IF(U10=100,"Completed","In Progress")))
U11: =IF($B11="","",IF(COUNTIF(G11:T11,"<>")=0,0,ROUND(COUNTIF(G11:T11,"Done")/COUNTIF(G11:T11,"<>")*100,0))) | V11: =IF($B11="","",IF($T11="Done","Failed",IF(U11=100,"Completed","In Progress")))
U12: =IF($B12="","",IF(COUNTIF(G12:T12,"<>")=0,0,ROUND(COUNTIF(G12:T12,"Done")/COUNTIF(G12:T12,"<>")*100,0))) | V12: =IF($B12="","",IF($T12="Done","Failed",IF(U12=100,"Completed","In Progress")))
U13: =IF($B13="","",IF(COUNTIF(G13:T13,"<>")=0,0,ROUND(COUNTIF(G13:T13,"Done")/COUNTIF(G13:T13,"<>")*100,0))) | V13: =IF($B13="","",IF($T13="Done","Failed",IF(U13=100,"Completed","In Progress")))
U14: =IF($B14="","",IF(COUNTIF(G14:T14,"<>")=0,0,ROUND(COUNTIF(G14:T14,"Done")/COUNTIF(G14:T14,"<>")*100,0))) | V14: =IF($B14="","",IF($T14="Done","Failed",IF(U14=100,"Completed","In Progress")))
U15: =IF($B15="","",IF(COUNTIF(G15:T15,"<>")=0,0,ROUND(COUNTIF(G15:T15,"Done")/COUNTIF(G15:T15,"<>")*100,0))) | V15: =IF($B15="","",IF($T15="Done","Failed",IF(U15=100,"Completed","In Progress")))
... U500: =IF($B500="","",IF(COUNTIF(G500:T500,"<>")=0,0,ROUND(COUNTIF(G500:T500,"Done")/COUNTIF(G500:T500,"<>")*100,0))) | V500: =IF($B500="","",IF($T500="Done","Failed",IF(U500=100,"Completed","In Progress")))

Sheet Today's Plan
A1: TODAY'S PLAN - every open task as on | E1: =TODAY()
A2: Auto-generated from the Task Log. Overdue tasks stay here until marked Completed. Nothing to type on this sheet.
A4: S.No | B4: Vertical | C4: Task Description | D4: Client / Customer | E4: Priority | F4: Due Date | G4: Event Date | H4: Event Type | I4: Days to Event | J4: Status | K4: Day Status | L4: Ageing (Days)
A5: =IFERROR(IF(MATCH(1,'Task Log'!$Q$2:$Q$500,0)>0,1,""),"") | B5: =IFERROR(IF(INDEX('Task Log'!$C$2:$C$500,MATCH(1,'Task Log'!$Q$2:$Q$500,0))="","",INDEX('Task Log'!$C$2:$C$500,MATCH(1,'Task Log'!$Q$2:$Q$500,0))),"") | C5: =IFERROR(IF(INDEX('Task Log'!$D$2:$D$500,MATCH(1,'Task Log'!$Q$2:$Q$500,0))="","",INDEX('Task Log'!$D$2:$D$500,MATCH(1,'Task Log'!$Q$2:$Q$500,0))),"") | D5: =IFERROR(IF(INDEX('Task Log'!$E$2:$E$500,MATCH(1,'Task Log'!$Q$2:$Q$500,0))="","",INDEX('Task Log'!$E$2:$E$500,MATCH(1,'Task Log'!$Q$2:$Q$500,0))),"") | E5: =IFERROR(IF(INDEX('Task Log'!$G$2:$G$500,MATCH(1,'Task Log'!$Q$2:$Q$500,0))="","",INDEX('Task Log'!$G$2:$G$500,MATCH(1,'Task Log'!$Q$2:$Q$500,0))),"") | F5: =IFERROR(IF(INDEX('Task Log'!$H$2:$H$500,MATCH(1,'Task Log'!$Q$2:$Q$500,0))="","",INDEX('Task Log'!$H$2:$H$500,MATCH(1,'Task Log'!$Q$2:$Q$500,0))),"") | G5: =IFERROR(IF(INDEX('Task Log'!$I$2:$I$500,MATCH(1,'Task Log'!$Q$2:$Q$500,0))="","",INDEX('Task Log'!$I$2:$I$500,MATCH(1,'Task Log'!$Q$2:$Q$500,0))),"") | H5: =IFERROR(IF(INDEX('Task Log'!$J$2:$J$500,MATCH(1,'Task Log'!$Q$2:$Q$500,0))="","",INDEX('Task Log'!$J$2:$J$500,MATCH(1,'Task Log'!$Q$2:$Q$500,0))),"") | I5: =IFERROR(IF(INDEX('Task Log'!$O$2:$O$500,MATCH(1,'Task Log'!$Q$2:$Q$500,0))="","",INDEX('Task Log'!$O$2:$O$500,MATCH(1,'Task Log'!$Q$2:$Q$500,0))),"") | J5: =IFERROR(IF(INDEX('Task Log'!$K$2:$K$500,MATCH(1,'Task Log'!$Q$2:$Q$500,0))="","",INDEX('Task Log'!$K$2:$K$500,MATCH(1,'Task Log'!$Q$2:$Q$500,0))),"") | K5: =IFERROR(IF(INDEX('Task Log'!$N$2:$N$500,MATCH(1,'Task Log'!$Q$2:$Q$500,0))="","",INDEX('Task Log'!$N$2:$N$500,MATCH(1,'Task Log'!$Q$2:$Q$500,0))),"") | L5: =IFERROR(IF(INDEX('Task Log'!$P$2:$P$500,MATCH(1,'Task Log'!$Q$2:$Q$500,0))="","",INDEX('Task Log'!$P$2:$P$500,MATCH(1,'Task Log'!$Q$2:$Q$500,0))),"")
A6: =IFERROR(IF(MATCH(2,'Task Log'!$Q$2:$Q$500,0)>0,2,""),"") | B6: =IFERROR(IF(INDEX('Task Log'!$C$2:$C$500,MATCH(2,'Task Log'!$Q$2:$Q$500,0))="","",INDEX('Task Log'!$C$2:$C$500,MATCH(2,'Task Log'!$Q$2:$Q$500,0))),"") | C6: =IFERROR(IF(INDEX('Task Log'!$D$2:$D$500,MATCH(2,'Task Log'!$Q$2:$Q$500,0))="","",INDEX('Task Log'!$D$2:$D$500,MATCH(2,'Task Log'!$Q$2:$Q$500,0))),"") | D6: =IFERROR(IF(INDEX('Task Log'!$E$2:$E$500,MATCH(2,'Task Log'!$Q$2:$Q$500,0))="","",INDEX('Task Log'!$E$2:$E$500,MATCH(2,'Task Log'!$Q$2:$Q$500,0))),"") | E6: =IFERROR(IF(INDEX('Task Log'!$G$2:$G$500,MATCH(2,'Task Log'!$Q$2:$Q$500,0))="","",INDEX('Task Log'!$G$2:$G$500,MATCH(2,'Task Log'!$Q$2:$Q$500,0))),"") | F6: =IFERROR(IF(INDEX('Task Log'!$H$2:$H$500,MATCH(2,'Task Log'!$Q$2:$Q$500,0))="","",INDEX('Task Log'!$H$2:$H$500,MATCH(2,'Task Log'!$Q$2:$Q$500,0))),"") | G6: =IFERROR(IF(INDEX('Task Log'!$I$2:$I$500,MATCH(2,'Task Log'!$Q$2:$Q$500,0))="","",INDEX('Task Log'!$I$2:$I$500,MATCH(2,'Task Log'!$Q$2:$Q$500,0))),"") | H6: =IFERROR(IF(INDEX('Task Log'!$J$2:$J$500,MATCH(2,'Task Log'!$Q$2:$Q$500,0))="","",INDEX('Task Log'!$J$2:$J$500,MATCH(2,'Task Log'!$Q$2:$Q$500,0))),"") | I6: =IFERROR(IF(INDEX('Task Log'!$O$2:$O$500,MATCH(2,'Task Log'!$Q$2:$Q$500,0))="","",INDEX('Task Log'!$O$2:$O$500,MATCH(2,'Task Log'!$Q$2:$Q$500,0))),"") | J6: =IFERROR(IF(INDEX('Task Log'!$K$2:$K$500,MATCH(2,'Task Log'!$Q$2:$Q$500,0))="","",INDEX('Task Log'!$K$2:$K$500,MATCH(2,'Task Log'!$Q$2:$Q$500,0))),"") | K6: =IFERROR(IF(INDEX('Task Log'!$N$2:$N$500,MATCH(2,'Task Log'!$Q$2:$Q$500,0))="","",INDEX('Task Log'!$N$2:$N$500,MATCH(2,'Task Log'!$Q$2:$Q$500,0))),"") | L6: =IFERROR(IF(INDEX('Task Log'!$P$2:$P$500,MATCH(2,'Task Log'!$Q$2:$Q$500,0))="","",INDEX('Task Log'!$P$2:$P$500,MATCH(2,'Task Log'!$Q$2:$Q$500,0))),"")
A7: =IFERROR(IF(MATCH(3,'Task Log'!$Q$2:$Q$500,0)>0,3,""),"") | B7: =IFERROR(IF(INDEX('Task Log'!$C$2:$C$500,MATCH(3,'Task Log'!$Q$2:$Q$500,0))="","",INDEX('Task Log'!$C$2:$C$500,MATCH(3,'Task Log'!$Q$2:$Q$500,0))),"") | C7: =IFERROR(IF(INDEX('Task Log'!$D$2:$D$500,MATCH(3,'Task Log'!$Q$2:$Q$500,0))="","",INDEX('Task Log'!$D$2:$D$500,MATCH(3,'Task Log'!$Q$2:$Q$500,0))),"") | D7: =IFERROR(IF(INDEX('Task Log'!$E$2:$E$500,MATCH(3,'Task Log'!$Q$2:$Q$500,0))="","",INDEX('Task Log'!$E$2:$E$500,MATCH(3,'Task Log'!$Q$2:$Q$500,0))),"") | E7: =IFERROR(IF(INDEX('Task Log'!$G$2:$G$500,MATCH(3,'Task Log'!$Q$2:$Q$500,0))="","",INDEX('Task Log'!$G$2:$G$500,MATCH(3,'Task Log'!$Q$2:$Q$500,0))),"") | F7: =IFERROR(IF(INDEX('Task Log'!$H$2:$H$500,MATCH(3,'Task Log'!$Q$2:$Q$500,0))="","",INDEX('Task Log'!$H$2:$H$500,MATCH(3,'Task Log'!$Q$2:$Q$500,0))),"") | G7: =IFERROR(IF(INDEX('Task Log'!$I$2:$I$500,MATCH(3,'Task Log'!$Q$2:$Q$500,0))="","",INDEX('Task Log'!$I$2:$I$500,MATCH(3,'Task Log'!$Q$2:$Q$500,0))),"") | H7: =IFERROR(IF(INDEX('Task Log'!$J$2:$J$500,MATCH(3,'Task Log'!$Q$2:$Q$500,0))="","",INDEX('Task Log'!$J$2:$J$500,MATCH(3,'Task Log'!$Q$2:$Q$500,0))),"") | I7: =IFERROR(IF(INDEX('Task Log'!$O$2:$O$500,MATCH(3,'Task Log'!$Q$2:$Q$500,0))="","",INDEX('Task Log'!$O$2:$O$500,MATCH(3,'Task Log'!$Q$2:$Q$500,0))),"") | J7: =IFERROR(IF(INDEX('Task Log'!$K$2:$K$500,MATCH(3,'Task Log'!$Q$2:$Q$500,0))="","",INDEX('Task Log'!$K$2:$K$500,MATCH(3,'Task Log'!$Q$2:$Q$500,0))),"") | K7: =IFERROR(IF(INDEX('Task Log'!$N$2:$N$500,MATCH(3,'Task Log'!$Q$2:$Q$500,0))="","",INDEX('Task Log'!$N$2:$N$500,MATCH(3,'Task Log'!$Q$2:$Q$500,0))),"") | L7: =IFERROR(IF(INDEX('Task Log'!$P$2:$P$500,MATCH(3,'Task Log'!$Q$2:$Q$500,0))="","",INDEX('Task Log'!$P$2:$P$500,MATCH(3,'Task Log'!$Q$2:$Q$500,0))),"")
A8: =IFERROR(IF(MATCH(4,'Task Log'!$Q$2:$Q$500,0)>0,4,""),"") | B8: =IFERROR(IF(INDEX('Task Log'!$C$2:$C$500,MATCH(4,'Task Log'!$Q$2:$Q$500,0))="","",INDEX('Task Log'!$C$2:$C$500,MATCH(4,'Task Log'!$Q$2:$Q$500,0))),"") | C8: =IFERROR(IF(INDEX('Task Log'!$D$2:$D$500,MATCH(4,'Task Log'!$Q$2:$Q$500,0))="","",INDEX('Task Log'!$D$2:$D$500,MATCH(4,'Task Log'!$Q$2:$Q$500,0))),"") | D8: =IFERROR(IF(INDEX('Task Log'!$E$2:$E$500,MATCH(4,'Task Log'!$Q$2:$Q$500,0))="","",INDEX('Task Log'!$E$2:$E$500,MATCH(4,'Task Log'!$Q$2:$Q$500,0))),"") | E8: =IFERROR(IF(INDEX('Task Log'!$G$2:$G$500,MATCH(4,'Task Log'!$Q$2:$Q$500,0))="","",INDEX('Task Log'!$G$2:$G$500,MATCH(4,'Task Log'!$Q$2:$Q$500,0))),"") | F8: =IFERROR(IF(INDEX('Task Log'!$H$2:$H$500,MATCH(4,'Task Log'!$Q$2:$Q$500,0))="","",INDEX('Task Log'!$H$2:$H$500,MATCH(4,'Task Log'!$Q$2:$Q$500,0))),"") | G8: =IFERROR(IF(INDEX('Task Log'!$I$2:$I$500,MATCH(4,'Task Log'!$Q$2:$Q$500,0))="","",INDEX('Task Log'!$I$2:$I$500,MATCH(4,'Task Log'!$Q$2:$Q$500,0))),"") | H8: =IFERROR(IF(INDEX('Task Log'!$J$2:$J$500,MATCH(4,'Task Log'!$Q$2:$Q$500,0))="","",INDEX('Task Log'!$J$2:$J$500,MATCH(4,'Task Log'!$Q$2:$Q$500,0))),"") | I8: =IFERROR(IF(INDEX('Task Log'!$O$2:$O$500,MATCH(4,'Task Log'!$Q$2:$Q$500,0))="","",INDEX('Task Log'!$O$2:$O$500,MATCH(4,'Task Log'!$Q$2:$Q$500,0))),"") | J8: =IFERROR(IF(INDEX('Task Log'!$K$2:$K$500,MATCH(4,'Task Log'!$Q$2:$Q$500,0))="","",INDEX('Task Log'!$K$2:$K$500,MATCH(4,'Task Log'!$Q$2:$Q$500,0))),"") | K8: =IFERROR(IF(INDEX('Task Log'!$N$2:$N$500,MATCH(4,'Task Log'!$Q$2:$Q$500,0))="","",INDEX('Task Log'!$N$2:$N$500,MATCH(4,'Task Log'!$Q$2:$Q$500,0))),"") | L8: =IFERROR(IF(INDEX('Task Log'!$P$2:$P$500,MATCH(4,'Task Log'!$Q$2:$Q$500,0))="","",INDEX('Task Log'!$P$2:$P$500,MATCH(4,'Task Log'!$Q$2:$Q$500,0))),"")
A9: =IFERROR(IF(MATCH(5,'Task Log'!$Q$2:$Q$500,0)>0,5,""),"") | B9: =IFERROR(IF(INDEX('Task Log'!$C$2:$C$500,MATCH(5,'Task Log'!$Q$2:$Q$500,0))="","",INDEX('Task Log'!$C$2:$C$500,MATCH(5,'Task Log'!$Q$2:$Q$500,0))),"") | C9: =IFERROR(IF(INDEX('Task Log'!$D$2:$D$500,MATCH(5,'Task Log'!$Q$2:$Q$500,0))="","",INDEX('Task Log'!$D$2:$D$500,MATCH(5,'Task Log'!$Q$2:$Q$500,0))),"") | D9: =IFERROR(IF(INDEX('Task Log'!$E$2:$E$500,MATCH(5,'Task Log'!$Q$2:$Q$500,0))="","",INDEX('Task Log'!$E$2:$E$500,MATCH(5,'Task Log'!$Q$2:$Q$500,0))),"") | E9: =IFERROR(IF(INDEX('Task Log'!$G$2:$G$500,MATCH(5,'Task Log'!$Q$2:$Q$500,0))="","",INDEX('Task Log'!$G$2:$G$500,MATCH(5,'Task Log'!$Q$2:$Q$500,0))),"") | F9: =IFERROR(IF(INDEX('Task Log'!$H$2:$H$500,MATCH(5,'Task Log'!$Q$2:$Q$500,0))="","",INDEX('Task Log'!$H$2:$H$500,MATCH(5,'Task Log'!$Q$2:$Q$500,0))),"") | G9: =IFERROR(IF(INDEX('Task Log'!$I$2:$I$500,MATCH(5,'Task Log'!$Q$2:$Q$500,0))="","",INDEX('Task Log'!$I$2:$I$500,MATCH(5,'Task Log'!$Q$2:$Q$500,0))),"") | H9: =IFERROR(IF(INDEX('Task Log'!$J$2:$J$500,MATCH(5,'Task Log'!$Q$2:$Q$500,0))="","",INDEX('Task Log'!$J$2:$J$500,MATCH(5,'Task Log'!$Q$2:$Q$500,0))),"") | I9: =IFERROR(IF(INDEX('Task Log'!$O$2:$O$500,MATCH(5,'Task Log'!$Q$2:$Q$500,0))="","",INDEX('Task Log'!$O$2:$O$500,MATCH(5,'Task Log'!$Q$2:$Q$500,0))),"") | J9: =IFERROR(IF(INDEX('Task Log'!$K$2:$K$500,MATCH(5,'Task Log'!$Q$2:$Q$500,0))="","",INDEX('Task Log'!$K$2:$K$500,MATCH(5,'Task Log'!$Q$2:$Q$500,0))),"") | K9: =IFERROR(IF(INDEX('Task Log'!$N$2:$N$500,MATCH(5,'Task Log'!$Q$2:$Q$500,0))="","",INDEX('Task Log'!$N$2:$N$500,MATCH(5,'Task Log'!$Q$2:$Q$500,0))),"") | L9: =IFERROR(IF(INDEX('Task Log'!$P$2:$P$500,MATCH(5,'Task Log'!$Q$2:$Q$500,0))="","",INDEX('Task Log'!$P$2:$P$500,MATCH(5,'Task Log'!$Q$2:$Q$500,0))),"")
A10: =IFERROR(IF(MATCH(6,'Task Log'!$Q$2:$Q$500,0)>0,6,""),"") | B10: =IFERROR(IF(INDEX('Task Log'!$C$2:$C$500,MATCH(6,'Task Log'!$Q$2:$Q$500,0))="","",INDEX('Task Log'!$C$2:$C$500,MATCH(6,'Task Log'!$Q$2:$Q$500,0))),"") | C10: =IFERROR(IF(INDEX('Task Log'!$D$2:$D$500,MATCH(6,'Task Log'!$Q$2:$Q$500,0))="","",INDEX('Task Log'!$D$2:$D$500,MATCH(6,'Task Log'!$Q$2:$Q$500,0))),"") | D10: =IFERROR(IF(INDEX('Task Log'!$E$2:$E$500,MATCH(6,'Task Log'!$Q$2:$Q$500,0))="","",INDEX('Task Log'!$E$2:$E$500,MATCH(6,'Task Log'!$Q$2:$Q$500,0))),"") | E10: =IFERROR(IF(INDEX('Task Log'!$G$2:$G$500,MATCH(6,'Task Log'!$Q$2:$Q$500,0))="","",INDEX('Task Log'!$G$2:$G$500,MATCH(6,'Task Log'!$Q$2:$Q$500,0))),"") | F10: =IFERROR(IF(INDEX('Task Log'!$H$2:$H$500,MATCH(6,'Task Log'!$Q$2:$Q$500,0))="","",INDEX('Task Log'!$H$2:$H$500,MATCH(6,'Task Log'!$Q$2:$Q$500,0))),"") | G10: =IFERROR(IF(INDEX('Task Log'!$I$2:$I$500,MATCH(6,'Task Log'!$Q$2:$Q$500,0))="","",INDEX('Task Log'!$I$2:$I$500,MATCH(6,'Task Log'!$Q$2:$Q$500,0))),"") | H10: =IFERROR(IF(INDEX('Task Log'!$J$2:$J$500,MATCH(6,'Task Log'!$Q$2:$Q$500,0))="","",INDEX('Task Log'!$J$2:$J$500,MATCH(6,'Task Log'!$Q$2:$Q$500,0))),"") | I10: =IFERROR(IF(INDEX('Task Log'!$O$2:$O$500,MATCH(6,'Task Log'!$Q$2:$Q$500,0))="","",INDEX('Task Log'!$O$2:$O$500,MATCH(6,'Task Log'!$Q$2:$Q$500,0))),"") | J10: =IFERROR(IF(INDEX('Task Log'!$K$2:$K$500,MATCH(6,'Task Log'!$Q$2:$Q$500,0))="","",INDEX('Task Log'!$K$2:$K$500,MATCH(6,'Task Log'!$Q$2:$Q$500,0))),"") | K10: =IFERROR(IF(INDEX('Task Log'!$N$2:$N$500,MATCH(6,'Task Log'!$Q$2:$Q$500,0))="","",INDEX('Task Log'!$N$2:$N$500,MATCH(6,'Task Log'!$Q$2:$Q$500,0))),"") | L10: =IFERROR(IF(INDEX('Task Log'!$P$2:$P$500,MATCH(6,'Task Log'!$Q$2:$Q$500,0))="","",INDEX('Task Log'!$P$2:$P$500,MATCH(6,'Task Log'!$Q$2:$Q$500,0))),"")
A11: =IFERROR(IF(MATCH(7,'Task Log'!$Q$2:$Q$500,0)>0,7,""),"") | B11: =IFERROR(IF(INDEX('Task Log'!$C$2:$C$500,MATCH(7,'Task Log'!$Q$2:$Q$500,0))="","",INDEX('Task Log'!$C$2:$C$500,MATCH(7,'Task Log'!$Q$2:$Q$500,0))),"") | C11: =IFERROR(IF(INDEX('Task Log'!$D$2:$D$500,MATCH(7,'Task Log'!$Q$2:$Q$500,0))="","",INDEX('Task Log'!$D$2:$D$500,MATCH(7,'Task Log'!$Q$2:$Q$500,0))),"") | D11: =IFERROR(IF(INDEX('Task Log'!$E$2:$E$500,MATCH(7,'Task Log'!$Q$2:$Q$500,0))="","",INDEX('Task Log'!$E$2:$E$500,MATCH(7,'Task Log'!$Q$2:$Q$500,0))),"") | E11: =IFERROR(IF(INDEX('Task Log'!$G$2:$G$500,MATCH(7,'Task Log'!$Q$2:$Q$500,0))="","",INDEX('Task Log'!$G$2:$G$500,MATCH(7,'Task Log'!$Q$2:$Q$500,0))),"") | F11: =IFERROR(IF(INDEX('Task Log'!$H$2:$H$500,MATCH(7,'Task Log'!$Q$2:$Q$500,0))="","",INDEX('Task Log'!$H$2:$H$500,MATCH(7,'Task Log'!$Q$2:$Q$500,0))),"") | G11: =IFERROR(IF(INDEX('Task Log'!$I$2:$I$500,MATCH(7,'Task Log'!$Q$2:$Q$500,0))="","",INDEX('Task Log'!$I$2:$I$500,MATCH(7,'Task Log'!$Q$2:$Q$500,0))),"") | H11: =IFERROR(IF(INDEX('Task Log'!$J$2:$J$500,MATCH(7,'Task Log'!$Q$2:$Q$500,0))="","",INDEX('Task Log'!$J$2:$J$500,MATCH(7,'Task Log'!$Q$2:$Q$500,0))),"") | I11: =IFERROR(IF(INDEX('Task Log'!$O$2:$O$500,MATCH(7,'Task Log'!$Q$2:$Q$500,0))="","",INDEX('Task Log'!$O$2:$O$500,MATCH(7,'Task Log'!$Q$2:$Q$500,0))),"") | J11: =IFERROR(IF(INDEX('Task Log'!$K$2:$K$500,MATCH(7,'Task Log'!$Q$2:$Q$500,0))="","",INDEX('Task Log'!$K$2:$K$500,MATCH(7,'Task Log'!$Q$2:$Q$500,0))),"") | K11: =IFERROR(IF(INDEX('Task Log'!$N$2:$N$500,MATCH(7,'Task Log'!$Q$2:$Q$500,0))="","",INDEX('Task Log'!$N$2:$N$500,MATCH(7,'Task Log'!$Q$2:$Q$500,0))),"") | L11: =IFERROR(IF(INDEX('Task Log'!$P$2:$P$500,MATCH(7,'Task Log'!$Q$2:$Q$500,0))="","",INDEX('Task Log'!$P$2:$P$500,MATCH(7,'Task Log'!$Q$2:$Q$500,0))),"")
A12: =IFERROR(IF(MATCH(8,'Task Log'!$Q$2:$Q$500,0)>0,8,""),"") | B12: =IFERROR(IF(INDEX('Task Log'!$C$2:$C$500,MATCH(8,'Task Log'!$Q$2:$Q$500,0))="","",INDEX('Task Log'!$C$2:$C$500,MATCH(8,'Task Log'!$Q$2:$Q$500,0))),"") | C12: =IFERROR(IF(INDEX('Task Log'!$D$2:$D$500,MATCH(8,'Task Log'!$Q$2:$Q$500,0))="","",INDEX('Task Log'!$D$2:$D$500,MATCH(8,'Task Log'!$Q$2:$Q$500,0))),"") | D12: =IFERROR(IF(INDEX('Task Log'!$E$2:$E$500,MATCH(8,'Task Log'!$Q$2:$Q$500,0))="","",INDEX('Task Log'!$E$2:$E$500,MATCH(8,'Task Log'!$Q$2:$Q$500,0))),"") | E12: =IFERROR(IF(INDEX('Task Log'!$G$2:$G$500,MATCH(8,'Task Log'!$Q$2:$Q$500,0))="","",INDEX('Task Log'!$G$2:$G$500,MATCH(8,'Task Log'!$Q$2:$Q$500,0))),"") | F12: =IFERROR(IF(INDEX('Task Log'!$H$2:$H$500,MATCH(8,'Task Log'!$Q$2:$Q$500,0))="","",INDEX('Task Log'!$H$2:$H$500,MATCH(8,'Task Log'!$Q$2:$Q$500,0))),"") | G12: =IFERROR(IF(INDEX('Task Log'!$I$2:$I$500,MATCH(8,'Task Log'!$Q$2:$Q$500,0))="","",INDEX('Task Log'!$I$2:$I$500,MATCH(8,'Task Log'!$Q$2:$Q$500,0))),"") | H12: =IFERROR(IF(INDEX('Task Log'!$J$2:$J$500,MATCH(8,'Task Log'!$Q$2:$Q$500,0))="","",INDEX('Task Log'!$J$2:$J$500,MATCH(8,'Task Log'!$Q$2:$Q$500,0))),"") | I12: =IFERROR(IF(INDEX('Task Log'!$O$2:$O$500,MATCH(8,'Task Log'!$Q$2:$Q$500,0))="","",INDEX('Task Log'!$O$2:$O$500,MATCH(8,'Task Log'!$Q$2:$Q$500,0))),"") | J12: =IFERROR(IF(INDEX('Task Log'!$K$2:$K$500,MATCH(8,'Task Log'!$Q$2:$Q$500,0))="","",INDEX('Task Log'!$K$2:$K$500,MATCH(8,'Task Log'!$Q$2:$Q$500,0))),"") | K12: =IFERROR(IF(INDEX('Task Log'!$N$2:$N$500,MATCH(8,'Task Log'!$Q$2:$Q$500,0))="","",INDEX('Task Log'!$N$2:$N$500,MATCH(8,'Task Log'!$Q$2:$Q$500,0))),"") | L12: =IFERROR(IF(INDEX('Task Log'!$P$2:$P$500,MATCH(8,'Task Log'!$Q$2:$Q$500,0))="","",INDEX('Task Log'!$P$2:$P$500,MATCH(8,'Task Log'!$Q$2:$Q$500,0))),"")
A13: =IFERROR(IF(MATCH(9,'Task Log'!$Q$2:$Q$500,0)>0,9,""),"") | B13: =IFERROR(IF(INDEX('Task Log'!$C$2:$C$500,MATCH(9,'Task Log'!$Q$2:$Q$500,0))="","",INDEX('Task Log'!$C$2:$C$500,MATCH(9,'Task Log'!$Q$2:$Q$500,0))),"") | C13: =IFERROR(IF(INDEX('Task Log'!$D$2:$D$500,MATCH(9,'Task Log'!$Q$2:$Q$500,0))="","",INDEX('Task Log'!$D$2:$D$500,MATCH(9,'Task Log'!$Q$2:$Q$500,0))),"") | D13: =IFERROR(IF(INDEX('Task Log'!$E$2:$E$500,MATCH(9,'Task Log'!$Q$2:$Q$500,0))="","",INDEX('Task Log'!$E$2:$E$500,MATCH(9,'Task Log'!$Q$2:$Q$500,0))),"") | E13: =IFERROR(IF(INDEX('Task Log'!$G$2:$G$500,MATCH(9,'Task Log'!$Q$2:$Q$500,0))="","",INDEX('Task Log'!$G$2:$G$500,MATCH(9,'Task Log'!$Q$2:$Q$500,0))),"") | F13: =IFERROR(IF(INDEX('Task Log'!$H$2:$H$500,MATCH(9,'Task Log'!$Q$2:$Q$500,0))="","",INDEX('Task Log'!$H$2:$H$500,MATCH(9,'Task Log'!$Q$2:$Q$500,0))),"") | G13: =IFERROR(IF(INDEX('Task Log'!$I$2:$I$500,MATCH(9,'Task Log'!$Q$2:$Q$500,0))="","",INDEX('Task Log'!$I$2:$I$500,MATCH(9,'Task Log'!$Q$2:$Q$500,0))),"") | H13: =IFERROR(IF(INDEX('Task Log'!$J$2:$J$500,MATCH(9,'Task Log'!$Q$2:$Q$500,0))="","",INDEX('Task Log'!$J$2:$J$500,MATCH(9,'Task Log'!$Q$2:$Q$500,0))),"") | I13: =IFERROR(IF(INDEX('Task Log'!$O$2:$O$500,MATCH(9,'Task Log'!$Q$2:$Q$500,0))="","",INDEX('Task Log'!$O$2:$O$500,MATCH(9,'Task Log'!$Q$2:$Q$500,0))),"") | J13: =IFERROR(IF(INDEX('Task Log'!$K$2:$K$500,MATCH(9,'Task Log'!$Q$2:$Q$500,0))="","",INDEX('Task Log'!$K$2:$K$500,MATCH(9,'Task Log'!$Q$2:$Q$500,0))),"") | K13: =IFERROR(IF(INDEX('Task Log'!$N$2:$N$500,MATCH(9,'Task Log'!$Q$2:$Q$500,0))="","",INDEX('Task Log'!$N$2:$N$500,MATCH(9,'Task Log'!$Q$2:$Q$500,0))),"") | L13: =IFERROR(IF(INDEX('Task Log'!$P$2:$P$500,MATCH(9,'Task Log'!$Q$2:$Q$500,0))="","",INDEX('Task Log'!$P$2:$P$500,MATCH(9,'Task Log'!$Q$2:$Q$500,0))),"")
A14: =IFERROR(IF(MATCH(10,'Task Log'!$Q$2:$Q$500,0)>0,10,""),"") | B14: =IFERROR(IF(INDEX('Task Log'!$C$2:$C$500,MATCH(10,'Task Log'!$Q$2:$Q$500,0))="","",INDEX('Task Log'!$C$2:$C$500,MATCH(10,'Task Log'!$Q$2:$Q$500,0))),"") | C14: =IFERROR(IF(INDEX('Task Log'!$D$2:$D$500,MATCH(10,'Task Log'!$Q$2:$Q$500,0))="","",INDEX('Task Log'!$D$2:$D$500,MATCH(10,'Task Log'!$Q$2:$Q$500,0))),"") | D14: =IFERROR(IF(INDEX('Task Log'!$E$2:$E$500,MATCH(10,'Task Log'!$Q$2:$Q$500,0))="","",INDEX('Task Log'!$E$2:$E$500,MATCH(10,'Task Log'!$Q$2:$Q$500,0))),"") | E14: =IFERROR(IF(INDEX('Task Log'!$G$2:$G$500,MATCH(10,'Task Log'!$Q$2:$Q$500,0))="","",INDEX('Task Log'!$G$2:$G$500,MATCH(10,'Task Log'!$Q$2:$Q$500,0))),"") | F14: =IFERROR(IF(INDEX('Task Log'!$H$2:$H$500,MATCH(10,'Task Log'!$Q$2:$Q$500,0))="","",INDEX('Task Log'!$H$2:$H$500,MATCH(10,'Task Log'!$Q$2:$Q$500,0))),"") | G14: =IFERROR(IF(INDEX('Task Log'!$I$2:$I$500,MATCH(10,'Task Log'!$Q$2:$Q$500,0))="","",INDEX('Task Log'!$I$2:$I$500,MATCH(10,'Task Log'!$Q$2:$Q$500,0))),"") | H14: =IFERROR(IF(INDEX('Task Log'!$J$2:$J$500,MATCH(10,'Task Log'!$Q$2:$Q$500,0))="","",INDEX('Task Log'!$J$2:$J$500,MATCH(10,'Task Log'!$Q$2:$Q$500,0))),"") | I14: =IFERROR(IF(INDEX('Task Log'!$O$2:$O$500,MATCH(10,'Task Log'!$Q$2:$Q$500,0))="","",INDEX('Task Log'!$O$2:$O$500,MATCH(10,'Task Log'!$Q$2:$Q$500,0))),"") | J14: =IFERROR(IF(INDEX('Task Log'!$K$2:$K$500,MATCH(10,'Task Log'!$Q$2:$Q$500,0))="","",INDEX('Task Log'!$K$2:$K$500,MATCH(10,'Task Log'!$Q$2:$Q$500,0))),"") | K14: =IFERROR(IF(INDEX('Task Log'!$N$2:$N$500,MATCH(10,'Task Log'!$Q$2:$Q$500,0))="","",INDEX('Task Log'!$N$2:$N$500,MATCH(10,'Task Log'!$Q$2:$Q$500,0))),"") | L14: =IFERROR(IF(INDEX('Task Log'!$P$2:$P$500,MATCH(10,'Task Log'!$Q$2:$Q$500,0))="","",INDEX('Task Log'!$P$2:$P$500,MATCH(10,'Task Log'!$Q$2:$Q$500,0))),"")
A15: =IFERROR(IF(MATCH(11,'Task Log'!$Q$2:$Q$500,0)>0,11,""),"") | B15: =IFERROR(IF(INDEX('Task Log'!$C$2:$C$500,MATCH(11,'Task Log'!$Q$2:$Q$500,0))="","",INDEX('Task Log'!$C$2:$C$500,MATCH(11,'Task Log'!$Q$2:$Q$500,0))),"") | C15: =IFERROR(IF(INDEX('Task Log'!$D$2:$D$500,MATCH(11,'Task Log'!$Q$2:$Q$500,0))="","",INDEX('Task Log'!$D$2:$D$500,MATCH(11,'Task Log'!$Q$2:$Q$500,0))),"") | D15: =IFERROR(IF(INDEX('Task Log'!$E$2:$E$500,MATCH(11,'Task Log'!$Q$2:$Q$500,0))="","",INDEX('Task Log'!$E$2:$E$500,MATCH(11,'Task Log'!$Q$2:$Q$500,0))),"") | E15: =IFERROR(IF(INDEX('Task Log'!$G$2:$G$500,MATCH(11,'Task Log'!$Q$2:$Q$500,0))="","",INDEX('Task Log'!$G$2:$G$500,MATCH(11,'Task Log'!$Q$2:$Q$500,0))),"") | F15: =IFERROR(IF(INDEX('Task Log'!$H$2:$H$500,MATCH(11,'Task Log'!$Q$2:$Q$500,0))="","",INDEX('Task Log'!$H$2:$H$500,MATCH(11,'Task Log'!$Q$2:$Q$500,0))),"") | G15: =IFERROR(IF(INDEX('Task Log'!$I$2:$I$500,MATCH(11,'Task Log'!$Q$2:$Q$500,0))="","",INDEX('Task Log'!$I$2:$I$500,MATCH(11,'Task Log'!$Q$2:$Q$500,0))),"") | H15: =IFERROR(IF(INDEX('Task Log'!$J$2:$J$500,MATCH(11,'Task Log'!$Q$2:$Q$500,0))="","",INDEX('Task Log'!$J$2:$J$500,MATCH(11,'Task Log'!$Q$2:$Q$500,0))),"") | I15: =IFERROR(IF(INDEX('Task Log'!$O$2:$O$500,MATCH(11,'Task Log'!$Q$2:$Q$500,0))="","",INDEX('Task Log'!$O$2:$O$500,MATCH(11,'Task Log'!$Q$2:$Q$500,0))),"") | J15: =IFERROR(IF(INDEX('Task Log'!$K$2:$K$500,MATCH(11,'Task Log'!$Q$2:$Q$500,0))="","",INDEX('Task Log'!$K$2:$K$500,MATCH(11,'Task Log'!$Q$2:$Q$500,0))),"") | K15: =IFERROR(IF(INDEX('Task Log'!$N$2:$N$500,MATCH(11,'Task Log'!$Q$2:$Q$500,0))="","",INDEX('Task Log'!$N$2:$N$500,MATCH(11,'Task Log'!$Q$2:$Q$500,0))),"") | L15: =IFERROR(IF(INDEX('Task Log'!$P$2:$P$500,MATCH(11,'Task Log'!$Q$2:$Q$500,0))="","",INDEX('Task Log'!$P$2:$P$500,MATCH(11,'Task Log'!$Q$2:$Q$500,0))),"")
A16: =IFERROR(IF(MATCH(12,'Task Log'!$Q$2:$Q$500,0)>0,12,""),"") | B16: =IFERROR(IF(INDEX('Task Log'!$C$2:$C$500,MATCH(12,'Task Log'!$Q$2:$Q$500,0))="","",INDEX('Task Log'!$C$2:$C$500,MATCH(12,'Task Log'!$Q$2:$Q$500,0))),"") | C16: =IFERROR(IF(INDEX('Task Log'!$D$2:$D$500,MATCH(12,'Task Log'!$Q$2:$Q$500,0))="","",INDEX('Task Log'!$D$2:$D$500,MATCH(12,'Task Log'!$Q$2:$Q$500,0))),"") | D16: =IFERROR(IF(INDEX('Task Log'!$E$2:$E$500,MATCH(12,'Task Log'!$Q$2:$Q$500,0))="","",INDEX('Task Log'!$E$2:$E$500,MATCH(12,'Task Log'!$Q$2:$Q$500,0))),"") | E16: =IFERROR(IF(INDEX('Task Log'!$G$2:$G$500,MATCH(12,'Task Log'!$Q$2:$Q$500,0))="","",INDEX('Task Log'!$G$2:$G$500,MATCH(12,'Task Log'!$Q$2:$Q$500,0))),"") | F16: =IFERROR(IF(INDEX('Task Log'!$H$2:$H$500,MATCH(12,'Task Log'!$Q$2:$Q$500,0))="","",INDEX('Task Log'!$H$2:$H$500,MATCH(12,'Task Log'!$Q$2:$Q$500,0))),"") | G16: =IFERROR(IF(INDEX('Task Log'!$I$2:$I$500,MATCH(12,'Task Log'!$Q$2:$Q$500,0))="","",INDEX('Task Log'!$I$2:$I$500,MATCH(12,'Task Log'!$Q$2:$Q$500,0))),"") | H16: =IFERROR(IF(INDEX('Task Log'!$J$2:$J$500,MATCH(12,'Task Log'!$Q$2:$Q$500,0))="","",INDEX('Task Log'!$J$2:$J$500,MATCH(12,'Task Log'!$Q$2:$Q$500,0))),"") | I16: =IFERROR(IF(INDEX('Task Log'!$O$2:$O$500,MATCH(12,'Task Log'!$Q$2:$Q$500,0))="","",INDEX('Task Log'!$O$2:$O$500,MATCH(12,'Task Log'!$Q$2:$Q$500,0))),"") | J16: =IFERROR(IF(INDEX('Task Log'!$K$2:$K$500,MATCH(12,'Task Log'!$Q$2:$Q$500,0))="","",INDEX('Task Log'!$K$2:$K$500,MATCH(12,'Task Log'!$Q$2:$Q$500,0))),"") | K16: =IFERROR(IF(INDEX('Task Log'!$N$2:$N$500,MATCH(12,'Task Log'!$Q$2:$Q$500,0))="","",INDEX('Task Log'!$N$2:$N$500,MATCH(12,'Task Log'!$Q$2:$Q$500,0))),"") | L16: =IFERROR(IF(INDEX('Task Log'!$P$2:$P$500,MATCH(12,'Task Log'!$Q$2:$Q$500,0))="","",INDEX('Task Log'!$P$2:$P$500,MATCH(12,'Task Log'!$Q$2:$Q$500,0))),"")
A17: =IFERROR(IF(MATCH(13,'Task Log'!$Q$2:$Q$500,0)>0,13,""),"") | B17: =IFERROR(IF(INDEX('Task Log'!$C$2:$C$500,MATCH(13,'Task Log'!$Q$2:$Q$500,0))="","",INDEX('Task Log'!$C$2:$C$500,MATCH(13,'Task Log'!$Q$2:$Q$500,0))),"") | C17: =IFERROR(IF(INDEX('Task Log'!$D$2:$D$500,MATCH(13,'Task Log'!$Q$2:$Q$500,0))="","",INDEX('Task Log'!$D$2:$D$500,MATCH(13,'Task Log'!$Q$2:$Q$500,0))),"") | D17: =IFERROR(IF(INDEX('Task Log'!$E$2:$E$500,MATCH(13,'Task Log'!$Q$2:$Q$500,0))="","",INDEX('Task Log'!$E$2:$E$500,MATCH(13,'Task Log'!$Q$2:$Q$500,0))),"") | E17: =IFERROR(IF(INDEX('Task Log'!$G$2:$G$500,MATCH(13,'Task Log'!$Q$2:$Q$500,0))="","",INDEX('Task Log'!$G$2:$G$500,MATCH(13,'Task Log'!$Q$2:$Q$500,0))),"") | F17: =IFERROR(IF(INDEX('Task Log'!$H$2:$H$500,MATCH(13,'Task Log'!$Q$2:$Q$500,0))="","",INDEX('Task Log'!$H$2:$H$500,MATCH(13,'Task Log'!$Q$2:$Q$500,0))),"") | G17: =IFERROR(IF(INDEX('Task Log'!$I$2:$I$500,MATCH(13,'Task Log'!$Q$2:$Q$500,0))="","",INDEX('Task Log'!$I$2:$I$500,MATCH(13,'Task Log'!$Q$2:$Q$500,0))),"") | H17: =IFERROR(IF(INDEX('Task Log'!$J$2:$J$500,MATCH(13,'Task Log'!$Q$2:$Q$500,0))="","",INDEX('Task Log'!$J$2:$J$500,MATCH(13,'Task Log'!$Q$2:$Q$500,0))),"") | I17: =IFERROR(IF(INDEX('Task Log'!$O$2:$O$500,MATCH(13,'Task Log'!$Q$2:$Q$500,0))="","",INDEX('Task Log'!$O$2:$O$500,MATCH(13,'Task Log'!$Q$2:$Q$500,0))),"") | J17: =IFERROR(IF(INDEX('Task Log'!$K$2:$K$500,MATCH(13,'Task Log'!$Q$2:$Q$500,0))="","",INDEX('Task Log'!$K$2:$K$500,MATCH(13,'Task Log'!$Q$2:$Q$500,0))),"") | K17: =IFERROR(IF(INDEX('Task Log'!$N$2:$N$500,MATCH(13,'Task Log'!$Q$2:$Q$500,0))="","",INDEX('Task Log'!$N$2:$N$500,MATCH(13,'Task Log'!$Q$2:$Q$500,0))),"") | L17: =IFERROR(IF(INDEX('Task Log'!$P$2:$P$500,MATCH(13,'Task Log'!$Q$2:$Q$500,0))="","",INDEX('Task Log'!$P$2:$P$500,MATCH(13,'Task Log'!$Q$2:$Q$500,0))),"")
A18: =IFERROR(IF(MATCH(14,'Task Log'!$Q$2:$Q$500,0)>0,14,""),"") | B18: =IFERROR(IF(INDEX('Task Log'!$C$2:$C$500,MATCH(14,'Task Log'!$Q$2:$Q$500,0))="","",INDEX('Task Log'!$C$2:$C$500,MATCH(14,'Task Log'!$Q$2:$Q$500,0))),"") | C18: =IFERROR(IF(INDEX('Task Log'!$D$2:$D$500,MATCH(14,'Task Log'!$Q$2:$Q$500,0))="","",INDEX('Task Log'!$D$2:$D$500,MATCH(14,'Task Log'!$Q$2:$Q$500,0))),"") | D18: =IFERROR(IF(INDEX('Task Log'!$E$2:$E$500,MATCH(14,'Task Log'!$Q$2:$Q$500,0))="","",INDEX('Task Log'!$E$2:$E$500,MATCH(14,'Task Log'!$Q$2:$Q$500,0))),"") | E18: =IFERROR(IF(INDEX('Task Log'!$G$2:$G$500,MATCH(14,'Task Log'!$Q$2:$Q$500,0))="","",INDEX('Task Log'!$G$2:$G$500,MATCH(14,'Task Log'!$Q$2:$Q$500,0))),"") | F18: =IFERROR(IF(INDEX('Task Log'!$H$2:$H$500,MATCH(14,'Task Log'!$Q$2:$Q$500,0))="","",INDEX('Task Log'!$H$2:$H$500,MATCH(14,'Task Log'!$Q$2:$Q$500,0))),"") | G18: =IFERROR(IF(INDEX('Task Log'!$I$2:$I$500,MATCH(14,'Task Log'!$Q$2:$Q$500,0))="","",INDEX('Task Log'!$I$2:$I$500,MATCH(14,'Task Log'!$Q$2:$Q$500,0))),"") | H18: =IFERROR(IF(INDEX('Task Log'!$J$2:$J$500,MATCH(14,'Task Log'!$Q$2:$Q$500,0))="","",INDEX('Task Log'!$J$2:$J$500,MATCH(14,'Task Log'!$Q$2:$Q$500,0))),"") | I18: =IFERROR(IF(INDEX('Task Log'!$O$2:$O$500,MATCH(14,'Task Log'!$Q$2:$Q$500,0))="","",INDEX('Task Log'!$O$2:$O$500,MATCH(14,'Task Log'!$Q$2:$Q$500,0))),"") | J18: =IFERROR(IF(INDEX('Task Log'!$K$2:$K$500,MATCH(14,'Task Log'!$Q$2:$Q$500,0))="","",INDEX('Task Log'!$K$2:$K$500,MATCH(14,'Task Log'!$Q$2:$Q$500,0))),"") | K18: =IFERROR(IF(INDEX('Task Log'!$N$2:$N$500,MATCH(14,'Task Log'!$Q$2:$Q$500,0))="","",INDEX('Task Log'!$N$2:$N$500,MATCH(14,'Task Log'!$Q$2:$Q$500,0))),"") | L18: =IFERROR(IF(INDEX('Task Log'!$P$2:$P$500,MATCH(14,'Task Log'!$Q$2:$Q$500,0))="","",INDEX('Task Log'!$P$2:$P$500,MATCH(14,'Task Log'!$Q$2:$Q$500,0))),"")
A19: =IFERROR(IF(MATCH(15,'Task Log'!$Q$2:$Q$500,0)>0,15,""),"") | B19: =IFERROR(IF(INDEX('Task Log'!$C$2:$C$500,MATCH(15,'Task Log'!$Q$2:$Q$500,0))="","",INDEX('Task Log'!$C$2:$C$500,MATCH(15,'Task Log'!$Q$2:$Q$500,0))),"") | C19: =IFERROR(IF(INDEX('Task Log'!$D$2:$D$500,MATCH(15,'Task Log'!$Q$2:$Q$500,0))="","",INDEX('Task Log'!$D$2:$D$500,MATCH(15,'Task Log'!$Q$2:$Q$500,0))),"") | D19: =IFERROR(IF(INDEX('Task Log'!$E$2:$E$500,MATCH(15,'Task Log'!$Q$2:$Q$500,0))="","",INDEX('Task Log'!$E$2:$E$500,MATCH(15,'Task Log'!$Q$2:$Q$500,0))),"") | E19: =IFERROR(IF(INDEX('Task Log'!$G$2:$G$500,MATCH(15,'Task Log'!$Q$2:$Q$500,0))="","",INDEX('Task Log'!$G$2:$G$500,MATCH(15,'Task Log'!$Q$2:$Q$500,0))),"") | F19: =IFERROR(IF(INDEX('Task Log'!$H$2:$H$500,MATCH(15,'Task Log'!$Q$2:$Q$500,0))="","",INDEX('Task Log'!$H$2:$H$500,MATCH(15,'Task Log'!$Q$2:$Q$500,0))),"") | G19: =IFERROR(IF(INDEX('Task Log'!$I$2:$I$500,MATCH(15,'Task Log'!$Q$2:$Q$500,0))="","",INDEX('Task Log'!$I$2:$I$500,MATCH(15,'Task Log'!$Q$2:$Q$500,0))),"") | H19: =IFERROR(IF(INDEX('Task Log'!$J$2:$J$500,MATCH(15,'Task Log'!$Q$2:$Q$500,0))="","",INDEX('Task Log'!$J$2:$J$500,MATCH(15,'Task Log'!$Q$2:$Q$500,0))),"") | I19: =IFERROR(IF(INDEX('Task Log'!$O$2:$O$500,MATCH(15,'Task Log'!$Q$2:$Q$500,0))="","",INDEX('Task Log'!$O$2:$O$500,MATCH(15,'Task Log'!$Q$2:$Q$500,0))),"") | J19: =IFERROR(IF(INDEX('Task Log'!$K$2:$K$500,MATCH(15,'Task Log'!$Q$2:$Q$500,0))="","",INDEX('Task Log'!$K$2:$K$500,MATCH(15,'Task Log'!$Q$2:$Q$500,0))),"") | K19: =IFERROR(IF(INDEX('Task Log'!$N$2:$N$500,MATCH(15,'Task Log'!$Q$2:$Q$500,0))="","",INDEX('Task Log'!$N$2:$N$500,MATCH(15,'Task Log'!$Q$2:$Q$500,0))),"") | L19: =IFERROR(IF(INDEX('Task Log'!$P$2:$P$500,MATCH(15,'Task Log'!$Q$2:$Q$500,0))="","",INDEX('Task Log'!$P$2:$P$500,MATCH(15,'Task Log'!$Q$2:$Q$500,0))),"")
A20: =IFERROR(IF(MATCH(16,'Task Log'!$Q$2:$Q$500,0)>0,16,""),"") | B20: =IFERROR(IF(INDEX('Task Log'!$C$2:$C$500,MATCH(16,'Task Log'!$Q$2:$Q$500,0))="","",INDEX('Task Log'!$C$2:$C$500,MATCH(16,'Task Log'!$Q$2:$Q$500,0))),"") | C20: =IFERROR(IF(INDEX('Task Log'!$D$2:$D$500,MATCH(16,'Task Log'!$Q$2:$Q$500,0))="","",INDEX('Task Log'!$D$2:$D$500,MATCH(16,'Task Log'!$Q$2:$Q$500,0))),"") | D20: =IFERROR(IF(INDEX('Task Log'!$E$2:$E$500,MATCH(16,'Task Log'!$Q$2:$Q$500,0))="","",INDEX('Task Log'!$E$2:$E$500,MATCH(16,'Task Log'!$Q$2:$Q$500,0))),"") | E20: =IFERROR(IF(INDEX('Task Log'!$G$2:$G$500,MATCH(16,'Task Log'!$Q$2:$Q$500,0))="","",INDEX('Task Log'!$G$2:$G$500,MATCH(16,'Task Log'!$Q$2:$Q$500,0))),"") | F20: =IFERROR(IF(INDEX('Task Log'!$H$2:$H$500,MATCH(16,'Task Log'!$Q$2:$Q$500,0))="","",INDEX('Task Log'!$H$2:$H$500,MATCH(16,'Task Log'!$Q$2:$Q$500,0))),"") | G20: =IFERROR(IF(INDEX('Task Log'!$I$2:$I$500,MATCH(16,'Task Log'!$Q$2:$Q$500,0))="","",INDEX('Task Log'!$I$2:$I$500,MATCH(16,'Task Log'!$Q$2:$Q$500,0))),"") | H20: =IFERROR(IF(INDEX('Task Log'!$J$2:$J$500,MATCH(16,'Task Log'!$Q$2:$Q$500,0))="","",INDEX('Task Log'!$J$2:$J$500,MATCH(16,'Task Log'!$Q$2:$Q$500,0))),"") | I20: =IFERROR(IF(INDEX('Task Log'!$O$2:$O$500,MATCH(16,'Task Log'!$Q$2:$Q$500,0))="","",INDEX('Task Log'!$O$2:$O$500,MATCH(16,'Task Log'!$Q$2:$Q$500,0))),"") | J20: =IFERROR(IF(INDEX('Task Log'!$K$2:$K$500,MATCH(16,'Task Log'!$Q$2:$Q$500,0))="","",INDEX('Task Log'!$K$2:$K$500,MATCH(16,'Task Log'!$Q$2:$Q$500,0))),"") | K20: =IFERROR(IF(INDEX('Task Log'!$N$2:$N$500,MATCH(16,'Task Log'!$Q$2:$Q$500,0))="","",INDEX('Task Log'!$N$2:$N$500,MATCH(16,'Task Log'!$Q$2:$Q$500,0))),"") | L20: =IFERROR(IF(INDEX('Task Log'!$P$2:$P$500,MATCH(16,'Task Log'!$Q$2:$Q$500,0))="","",INDEX('Task Log'!$P$2:$P$500,MATCH(16,'Task Log'!$Q$2:$Q$500,0))),"")
A21: =IFERROR(IF(MATCH(17,'Task Log'!$Q$2:$Q$500,0)>0,17,""),"") | B21: =IFERROR(IF(INDEX('Task Log'!$C$2:$C$500,MATCH(17,'Task Log'!$Q$2:$Q$500,0))="","",INDEX('Task Log'!$C$2:$C$500,MATCH(17,'Task Log'!$Q$2:$Q$500,0))),"") | C21: =IFERROR(IF(INDEX('Task Log'!$D$2:$D$500,MATCH(17,'Task Log'!$Q$2:$Q$500,0))="","",INDEX('Task Log'!$D$2:$D$500,MATCH(17,'Task Log'!$Q$2:$Q$500,0))),"") | D21: =IFERROR(IF(INDEX('Task Log'!$E$2:$E$500,MATCH(17,'Task Log'!$Q$2:$Q$500,0))="","",INDEX('Task Log'!$E$2:$E$500,MATCH(17,'Task Log'!$Q$2:$Q$500,0))),"") | E21: =IFERROR(IF(INDEX('Task Log'!$G$2:$G$500,MATCH(17,'Task Log'!$Q$2:$Q$500,0))="","",INDEX('Task Log'!$G$2:$G$500,MATCH(17,'Task Log'!$Q$2:$Q$500,0))),"") | F21: =IFERROR(IF(INDEX('Task Log'!$H$2:$H$500,MATCH(17,'Task Log'!$Q$2:$Q$500,0))="","",INDEX('Task Log'!$H$2:$H$500,MATCH(17,'Task Log'!$Q$2:$Q$500,0))),"") | G21: =IFERROR(IF(INDEX('Task Log'!$I$2:$I$500,MATCH(17,'Task Log'!$Q$2:$Q$500,0))="","",INDEX('Task Log'!$I$2:$I$500,MATCH(17,'Task Log'!$Q$2:$Q$500,0))),"") | H21: =IFERROR(IF(INDEX('Task Log'!$J$2:$J$500,MATCH(17,'Task Log'!$Q$2:$Q$500,0))="","",INDEX('Task Log'!$J$2:$J$500,MATCH(17,'Task Log'!$Q$2:$Q$500,0))),"") | I21: =IFERROR(IF(INDEX('Task Log'!$O$2:$O$500,MATCH(17,'Task Log'!$Q$2:$Q$500,0))="","",INDEX('Task Log'!$O$2:$O$500,MATCH(17,'Task Log'!$Q$2:$Q$500,0))),"") | J21: =IFERROR(IF(INDEX('Task Log'!$K$2:$K$500,MATCH(17,'Task Log'!$Q$2:$Q$500,0))="","",INDEX('Task Log'!$K$2:$K$500,MATCH(17,'Task Log'!$Q$2:$Q$500,0))),"") | K21: =IFERROR(IF(INDEX('Task Log'!$N$2:$N$500,MATCH(17,'Task Log'!$Q$2:$Q$500,0))="","",INDEX('Task Log'!$N$2:$N$500,MATCH(17,'Task Log'!$Q$2:$Q$500,0))),"") | L21: =IFERROR(IF(INDEX('Task Log'!$P$2:$P$500,MATCH(17,'Task Log'!$Q$2:$Q$500,0))="","",INDEX('Task Log'!$P$2:$P$500,MATCH(17,'Task Log'!$Q$2:$Q$500,0))),"")
A22: =IFERROR(IF(MATCH(18,'Task Log'!$Q$2:$Q$500,0)>0,18,""),"") | B22: =IFERROR(IF(INDEX('Task Log'!$C$2:$C$500,MATCH(18,'Task Log'!$Q$2:$Q$500,0))="","",INDEX('Task Log'!$C$2:$C$500,MATCH(18,'Task Log'!$Q$2:$Q$500,0))),"") | C22: =IFERROR(IF(INDEX('Task Log'!$D$2:$D$500,MATCH(18,'Task Log'!$Q$2:$Q$500,0))="","",INDEX('Task Log'!$D$2:$D$500,MATCH(18,'Task Log'!$Q$2:$Q$500,0))),"") | D22: =IFERROR(IF(INDEX('Task Log'!$E$2:$E$500,MATCH(18,'Task Log'!$Q$2:$Q$500,0))="","",INDEX('Task Log'!$E$2:$E$500,MATCH(18,'Task Log'!$Q$2:$Q$500,0))),"") | E22: =IFERROR(IF(INDEX('Task Log'!$G$2:$G$500,MATCH(18,'Task Log'!$Q$2:$Q$500,0))="","",INDEX('Task Log'!$G$2:$G$500,MATCH(18,'Task Log'!$Q$2:$Q$500,0))),"") | F22: =IFERROR(IF(INDEX('Task Log'!$H$2:$H$500,MATCH(18,'Task Log'!$Q$2:$Q$500,0))="","",INDEX('Task Log'!$H$2:$H$500,MATCH(18,'Task Log'!$Q$2:$Q$500,0))),"") | G22: =IFERROR(IF(INDEX('Task Log'!$I$2:$I$500,MATCH(18,'Task Log'!$Q$2:$Q$500,0))="","",INDEX('Task Log'!$I$2:$I$500,MATCH(18,'Task Log'!$Q$2:$Q$500,0))),"") | H22: =IFERROR(IF(INDEX('Task Log'!$J$2:$J$500,MATCH(18,'Task Log'!$Q$2:$Q$500,0))="","",INDEX('Task Log'!$J$2:$J$500,MATCH(18,'Task Log'!$Q$2:$Q$500,0))),"") | I22: =IFERROR(IF(INDEX('Task Log'!$O$2:$O$500,MATCH(18,'Task Log'!$Q$2:$Q$500,0))="","",INDEX('Task Log'!$O$2:$O$500,MATCH(18,'Task Log'!$Q$2:$Q$500,0))),"") | J22: =IFERROR(IF(INDEX('Task Log'!$K$2:$K$500,MATCH(18,'Task Log'!$Q$2:$Q$500,0))="","",INDEX('Task Log'!$K$2:$K$500,MATCH(18,'Task Log'!$Q$2:$Q$500,0))),"") | K22: =IFERROR(IF(INDEX('Task Log'!$N$2:$N$500,MATCH(18,'Task Log'!$Q$2:$Q$500,0))="","",INDEX('Task Log'!$N$2:$N$500,MATCH(18,'Task Log'!$Q$2:$Q$500,0))),"") | L22: =IFERROR(IF(INDEX('Task Log'!$P$2:$P$500,MATCH(18,'Task Log'!$Q$2:$Q$500,0))="","",INDEX('Task Log'!$P$2:$P$500,MATCH(18,'Task Log'!$Q$2:$Q$500,0))),"")
A23: =IFERROR(IF(MATCH(19,'Task Log'!$Q$2:$Q$500,0)>0,19,""),"") | B23: =IFERROR(IF(INDEX('Task Log'!$C$2:$C$500,MATCH(19,'Task Log'!$Q$2:$Q$500,0))="","",INDEX('Task Log'!$C$2:$C$500,MATCH(19,'Task Log'!$Q$2:$Q$500,0))),"") | C23: =IFERROR(IF(INDEX('Task Log'!$D$2:$D$500,MATCH(19,'Task Log'!$Q$2:$Q$500,0))="","",INDEX('Task Log'!$D$2:$D$500,MATCH(19,'Task Log'!$Q$2:$Q$500,0))),"") | D23: =IFERROR(IF(INDEX('Task Log'!$E$2:$E$500,MATCH(19,'Task Log'!$Q$2:$Q$500,0))="","",INDEX('Task Log'!$E$2:$E$500,MATCH(19,'Task Log'!$Q$2:$Q$500,0))),"") | E23: =IFERROR(IF(INDEX('Task Log'!$G$2:$G$500,MATCH(19,'Task Log'!$Q$2:$Q$500,0))="","",INDEX('Task Log'!$G$2:$G$500,MATCH(19,'Task Log'!$Q$2:$Q$500,0))),"") | F23: =IFERROR(IF(INDEX('Task Log'!$H$2:$H$500,MATCH(19,'Task Log'!$Q$2:$Q$500,0))="","",INDEX('Task Log'!$H$2:$H$500,MATCH(19,'Task Log'!$Q$2:$Q$500,0))),"") | G23: =IFERROR(IF(INDEX('Task Log'!$I$2:$I$500,MATCH(19,'Task Log'!$Q$2:$Q$500,0))="","",INDEX('Task Log'!$I$2:$I$500,MATCH(19,'Task Log'!$Q$2:$Q$500,0))),"") | H23: =IFERROR(IF(INDEX('Task Log'!$J$2:$J$500,MATCH(19,'Task Log'!$Q$2:$Q$500,0))="","",INDEX('Task Log'!$J$2:$J$500,MATCH(19,'Task Log'!$Q$2:$Q$500,0))),"") | I23: =IFERROR(IF(INDEX('Task Log'!$O$2:$O$500,MATCH(19,'Task Log'!$Q$2:$Q$500,0))="","",INDEX('Task Log'!$O$2:$O$500,MATCH(19,'Task Log'!$Q$2:$Q$500,0))),"") | J23: =IFERROR(IF(INDEX('Task Log'!$K$2:$K$500,MATCH(19,'Task Log'!$Q$2:$Q$500,0))="","",INDEX('Task Log'!$K$2:$K$500,MATCH(19,'Task Log'!$Q$2:$Q$500,0))),"") | K23: =IFERROR(IF(INDEX('Task Log'!$N$2:$N$500,MATCH(19,'Task Log'!$Q$2:$Q$500,0))="","",INDEX('Task Log'!$N$2:$N$500,MATCH(19,'Task Log'!$Q$2:$Q$500,0))),"") | L23: =IFERROR(IF(INDEX('Task Log'!$P$2:$P$500,MATCH(19,'Task Log'!$Q$2:$Q$500,0))="","",INDEX('Task Log'!$P$2:$P$500,MATCH(19,'Task Log'!$Q$2:$Q$500,0))),"")
A24: =IFERROR(IF(MATCH(20,'Task Log'!$Q$2:$Q$500,0)>0,20,""),"") | B24: =IFERROR(IF(INDEX('Task Log'!$C$2:$C$500,MATCH(20,'Task Log'!$Q$2:$Q$500,0))="","",INDEX('Task Log'!$C$2:$C$500,MATCH(20,'Task Log'!$Q$2:$Q$500,0))),"") | C24: =IFERROR(IF(INDEX('Task Log'!$D$2:$D$500,MATCH(20,'Task Log'!$Q$2:$Q$500,0))="","",INDEX('Task Log'!$D$2:$D$500,MATCH(20,'Task Log'!$Q$2:$Q$500,0))),"") | D24: =IFERROR(IF(INDEX('Task Log'!$E$2:$E$500,MATCH(20,'Task Log'!$Q$2:$Q$500,0))="","",INDEX('Task Log'!$E$2:$E$500,MATCH(20,'Task Log'!$Q$2:$Q$500,0))),"") | E24: =IFERROR(IF(INDEX('Task Log'!$G$2:$G$500,MATCH(20,'Task Log'!$Q$2:$Q$500,0))="","",INDEX('Task Log'!$G$2:$G$500,MATCH(20,'Task Log'!$Q$2:$Q$500,0))),"") | F24: =IFERROR(IF(INDEX('Task Log'!$H$2:$H$500,MATCH(20,'Task Log'!$Q$2:$Q$500,0))="","",INDEX('Task Log'!$H$2:$H$500,MATCH(20,'Task Log'!$Q$2:$Q$500,0))),"") | G24: =IFERROR(IF(INDEX('Task Log'!$I$2:$I$500,MATCH(20,'Task Log'!$Q$2:$Q$500,0))="","",INDEX('Task Log'!$I$2:$I$500,MATCH(20,'Task Log'!$Q$2:$Q$500,0))),"") | H24: =IFERROR(IF(INDEX('Task Log'!$J$2:$J$500,MATCH(20,'Task Log'!$Q$2:$Q$500,0))="","",INDEX('Task Log'!$J$2:$J$500,MATCH(20,'Task Log'!$Q$2:$Q$500,0))),"") | I24: =IFERROR(IF(INDEX('Task Log'!$O$2:$O$500,MATCH(20,'Task Log'!$Q$2:$Q$500,0))="","",INDEX('Task Log'!$O$2:$O$500,MATCH(20,'Task Log'!$Q$2:$Q$500,0))),"") | J24: =IFERROR(IF(INDEX('Task Log'!$K$2:$K$500,MATCH(20,'Task Log'!$Q$2:$Q$500,0))="","",INDEX('Task Log'!$K$2:$K$500,MATCH(20,'Task Log'!$Q$2:$Q$500,0))),"") | K24: =IFERROR(IF(INDEX('Task Log'!$N$2:$N$500,MATCH(20,'Task Log'!$Q$2:$Q$500,0))="","",INDEX('Task Log'!$N$2:$N$500,MATCH(20,'Task Log'!$Q$2:$Q$500,0))),"") | L24: =IFERROR(IF(INDEX('Task Log'!$P$2:$P$500,MATCH(20,'Task Log'!$Q$2:$Q$500,0))="","",INDEX('Task Log'!$P$2:$P$500,MATCH(20,'Task Log'!$Q$2:$Q$500,0))),"")
A25: =IFERROR(IF(MATCH(21,'Task Log'!$Q$2:$Q$500,0)>0,21,""),"") | B25: =IFERROR(IF(INDEX('Task Log'!$C$2:$C$500,MATCH(21,'Task Log'!$Q$2:$Q$500,0))="","",INDEX('Task Log'!$C$2:$C$500,MATCH(21,'Task Log'!$Q$2:$Q$500,0))),"") | C25: =IFERROR(IF(INDEX('Task Log'!$D$2:$D$500,MATCH(21,'Task Log'!$Q$2:$Q$500,0))="","",INDEX('Task Log'!$D$2:$D$500,MATCH(21,'Task Log'!$Q$2:$Q$500,0))),"") | D25: =IFERROR(IF(INDEX('Task Log'!$E$2:$E$500,MATCH(21,'Task Log'!$Q$2:$Q$500,0))="","",INDEX('Task Log'!$E$2:$E$500,MATCH(21,'Task Log'!$Q$2:$Q$500,0))),"") | E25: =IFERROR(IF(INDEX('Task Log'!$G$2:$G$500,MATCH(21,'Task Log'!$Q$2:$Q$500,0))="","",INDEX('Task Log'!$G$2:$G$500,MATCH(21,'Task Log'!$Q$2:$Q$500,0))),"") | F25: =IFERROR(IF(INDEX('Task Log'!$H$2:$H$500,MATCH(21,'Task Log'!$Q$2:$Q$500,0))="","",INDEX('Task Log'!$H$2:$H$500,MATCH(21,'Task Log'!$Q$2:$Q$500,0))),"") | G25: =IFERROR(IF(INDEX('Task Log'!$I$2:$I$500,MATCH(21,'Task Log'!$Q$2:$Q$500,0))="","",INDEX('Task Log'!$I$2:$I$500,MATCH(21,'Task Log'!$Q$2:$Q$500,0))),"") | H25: =IFERROR(IF(INDEX('Task Log'!$J$2:$J$500,MATCH(21,'Task Log'!$Q$2:$Q$500,0))="","",INDEX('Task Log'!$J$2:$J$500,MATCH(21,'Task Log'!$Q$2:$Q$500,0))),"") | I25: =IFERROR(IF(INDEX('Task Log'!$O$2:$O$500,MATCH(21,'Task Log'!$Q$2:$Q$500,0))="","",INDEX('Task Log'!$O$2:$O$500,MATCH(21,'Task Log'!$Q$2:$Q$500,0))),"") | J25: =IFERROR(IF(INDEX('Task Log'!$K$2:$K$500,MATCH(21,'Task Log'!$Q$2:$Q$500,0))="","",INDEX('Task Log'!$K$2:$K$500,MATCH(21,'Task Log'!$Q$2:$Q$500,0))),"") | K25: =IFERROR(IF(INDEX('Task Log'!$N$2:$N$500,MATCH(21,'Task Log'!$Q$2:$Q$500,0))="","",INDEX('Task Log'!$N$2:$N$500,MATCH(21,'Task Log'!$Q$2:$Q$500,0))),"") | L25: =IFERROR(IF(INDEX('Task Log'!$P$2:$P$500,MATCH(21,'Task Log'!$Q$2:$Q$500,0))="","",INDEX('Task Log'!$P$2:$P$500,MATCH(21,'Task Log'!$Q$2:$Q$500,0))),"")
A26: =IFERROR(IF(MATCH(22,'Task Log'!$Q$2:$Q$500,0)>0,22,""),"") | B26: =IFERROR(IF(INDEX('Task Log'!$C$2:$C$500,MATCH(22,'Task Log'!$Q$2:$Q$500,0))="","",INDEX('Task Log'!$C$2:$C$500,MATCH(22,'Task Log'!$Q$2:$Q$500,0))),"") | C26: =IFERROR(IF(INDEX('Task Log'!$D$2:$D$500,MATCH(22,'Task Log'!$Q$2:$Q$500,0))="","",INDEX('Task Log'!$D$2:$D$500,MATCH(22,'Task Log'!$Q$2:$Q$500,0))),"") | D26: =IFERROR(IF(INDEX('Task Log'!$E$2:$E$500,MATCH(22,'Task Log'!$Q$2:$Q$500,0))="","",INDEX('Task Log'!$E$2:$E$500,MATCH(22,'Task Log'!$Q$2:$Q$500,0))),"") | E26: =IFERROR(IF(INDEX('Task Log'!$G$2:$G$500,MATCH(22,'Task Log'!$Q$2:$Q$500,0))="","",INDEX('Task Log'!$G$2:$G$500,MATCH(22,'Task Log'!$Q$2:$Q$500,0))),"") | F26: =IFERROR(IF(INDEX('Task Log'!$H$2:$H$500,MATCH(22,'Task Log'!$Q$2:$Q$500,0))="","",INDEX('Task Log'!$H$2:$H$500,MATCH(22,'Task Log'!$Q$2:$Q$500,0))),"") | G26: =IFERROR(IF(INDEX('Task Log'!$I$2:$I$500,MATCH(22,'Task Log'!$Q$2:$Q$500,0))="","",INDEX('Task Log'!$I$2:$I$500,MATCH(22,'Task Log'!$Q$2:$Q$500,0))),"") | H26: =IFERROR(IF(INDEX('Task Log'!$J$2:$J$500,MATCH(22,'Task Log'!$Q$2:$Q$500,0))="","",INDEX('Task Log'!$J$2:$J$500,MATCH(22,'Task Log'!$Q$2:$Q$500,0))),"") | I26: =IFERROR(IF(INDEX('Task Log'!$O$2:$O$500,MATCH(22,'Task Log'!$Q$2:$Q$500,0))="","",INDEX('Task Log'!$O$2:$O$500,MATCH(22,'Task Log'!$Q$2:$Q$500,0))),"") | J26: =IFERROR(IF(INDEX('Task Log'!$K$2:$K$500,MATCH(22,'Task Log'!$Q$2:$Q$500,0))="","",INDEX('Task Log'!$K$2:$K$500,MATCH(22,'Task Log'!$Q$2:$Q$500,0))),"") | K26: =IFERROR(IF(INDEX('Task Log'!$N$2:$N$500,MATCH(22,'Task Log'!$Q$2:$Q$500,0))="","",INDEX('Task Log'!$N$2:$N$500,MATCH(22,'Task Log'!$Q$2:$Q$500,0))),"") | L26: =IFERROR(IF(INDEX('Task Log'!$P$2:$P$500,MATCH(22,'Task Log'!$Q$2:$Q$500,0))="","",INDEX('Task Log'!$P$2:$P$500,MATCH(22,'Task Log'!$Q$2:$Q$500,0))),"")
A27: =IFERROR(IF(MATCH(23,'Task Log'!$Q$2:$Q$500,0)>0,23,""),"") | B27: =IFERROR(IF(INDEX('Task Log'!$C$2:$C$500,MATCH(23,'Task Log'!$Q$2:$Q$500,0))="","",INDEX('Task Log'!$C$2:$C$500,MATCH(23,'Task Log'!$Q$2:$Q$500,0))),"") | C27: =IFERROR(IF(INDEX('Task Log'!$D$2:$D$500,MATCH(23,'Task Log'!$Q$2:$Q$500,0))="","",INDEX('Task Log'!$D$2:$D$500,MATCH(23,'Task Log'!$Q$2:$Q$500,0))),"") | D27: =IFERROR(IF(INDEX('Task Log'!$E$2:$E$500,MATCH(23,'Task Log'!$Q$2:$Q$500,0))="","",INDEX('Task Log'!$E$2:$E$500,MATCH(23,'Task Log'!$Q$2:$Q$500,0))),"") | E27: =IFERROR(IF(INDEX('Task Log'!$G$2:$G$500,MATCH(23,'Task Log'!$Q$2:$Q$500,0))="","",INDEX('Task Log'!$G$2:$G$500,MATCH(23,'Task Log'!$Q$2:$Q$500,0))),"") | F27: =IFERROR(IF(INDEX('Task Log'!$H$2:$H$500,MATCH(23,'Task Log'!$Q$2:$Q$500,0))="","",INDEX('Task Log'!$H$2:$H$500,MATCH(23,'Task Log'!$Q$2:$Q$500,0))),"") | G27: =IFERROR(IF(INDEX('Task Log'!$I$2:$I$500,MATCH(23,'Task Log'!$Q$2:$Q$500,0))="","",INDEX('Task Log'!$I$2:$I$500,MATCH(23,'Task Log'!$Q$2:$Q$500,0))),"") | H27: =IFERROR(IF(INDEX('Task Log'!$J$2:$J$500,MATCH(23,'Task Log'!$Q$2:$Q$500,0))="","",INDEX('Task Log'!$J$2:$J$500,MATCH(23,'Task Log'!$Q$2:$Q$500,0))),"") | I27: =IFERROR(IF(INDEX('Task Log'!$O$2:$O$500,MATCH(23,'Task Log'!$Q$2:$Q$500,0))="","",INDEX('Task Log'!$O$2:$O$500,MATCH(23,'Task Log'!$Q$2:$Q$500,0))),"") | J27: =IFERROR(IF(INDEX('Task Log'!$K$2:$K$500,MATCH(23,'Task Log'!$Q$2:$Q$500,0))="","",INDEX('Task Log'!$K$2:$K$500,MATCH(23,'Task Log'!$Q$2:$Q$500,0))),"") | K27: =IFERROR(IF(INDEX('Task Log'!$N$2:$N$500,MATCH(23,'Task Log'!$Q$2:$Q$500,0))="","",INDEX('Task Log'!$N$2:$N$500,MATCH(23,'Task Log'!$Q$2:$Q$500,0))),"") | L27: =IFERROR(IF(INDEX('Task Log'!$P$2:$P$500,MATCH(23,'Task Log'!$Q$2:$Q$500,0))="","",INDEX('Task Log'!$P$2:$P$500,MATCH(23,'Task Log'!$Q$2:$Q$500,0))),"")
